2013-09-01 16:26:37,826 - Tornado - ERROR - error message
2013-09-01 16:26:37,827 - Tornado - CRITICAL - critical message
2013-09-03 14:06:58,299 - Tornado - ERROR - Traceback (most recent call last):
  File "server.py", line 22, in <module>
    tornado.ioloop.IOLoop.instance().start()
  File "/usr/local/lib/python2.7/dist-packages/tornado/ioloop.py", line 646, in start
    event_pairs = self._impl.poll(poll_timeout)
KeyboardInterrupt

2013-09-05 17:12:07,266 - app - ERROR - Exception on / [GET]
Traceback (most recent call last):
  File "/usr/local/lib/python2.7/dist-packages/flask/app.py", line 1817, in wsgi_app
    response = self.full_dispatch_request()
  File "/usr/local/lib/python2.7/dist-packages/flask/app.py", line 1477, in full_dispatch_request
    rv = self.handle_user_exception(e)
  File "/usr/local/lib/python2.7/dist-packages/flask/app.py", line 1381, in handle_user_exception
    reraise(exc_type, exc_value, tb)
  File "/usr/local/lib/python2.7/dist-packages/flask/app.py", line 1475, in full_dispatch_request
    rv = self.dispatch_request()
  File "/usr/local/lib/python2.7/dist-packages/flask/app.py", line 1461, in dispatch_request
    return self.view_functions[rule.endpoint](**req.view_args)
  File "/home/yj/wyzq/server/app.py", line 39, in index
    return render_template('index.html', **locals())
  File "/usr/local/lib/python2.7/dist-packages/flask/templating.py", line 128, in render_template
    context, ctx.app)
  File "/usr/local/lib/python2.7/dist-packages/flask/templating.py", line 110, in _render
    rv = template.render(context)
  File "/usr/local/lib/python2.7/dist-packages/jinja2/environment.py", line 969, in render
    return self.environment.handle_exception(exc_info, True)
  File "/usr/local/lib/python2.7/dist-packages/jinja2/environment.py", line 742, in handle_exception
    reraise(exc_type, exc_value, tb)
  File "/home/yj/wyzq/server/templates/index.html", line 72, in top-level template code
    <span>{{book.category.name}}|</span>
  File "/usr/local/lib/python2.7/dist-packages/jinja2/environment.py", line 397, in getattr
    return getattr(obj, attribute)
  File "/home/yj/wyzq/server/models.py", line 35, in category
    category = db_session.query(Category).filter_by(id=self.category_id).one()
  File "/usr/local/lib/python2.7/dist-packages/sqlalchemy/orm/query.py", line 2306, in one
    ret = list(self)
  File "/usr/local/lib/python2.7/dist-packages/sqlalchemy/orm/query.py", line 2349, in __iter__
    return self._execute_and_instances(context)
  File "/usr/local/lib/python2.7/dist-packages/sqlalchemy/orm/query.py", line 2364, in _execute_and_instances
    result = conn.execute(querycontext.statement, self._params)
  File "/usr/local/lib/python2.7/dist-packages/sqlalchemy/engine/base.py", line 662, in execute
    params)
  File "/usr/local/lib/python2.7/dist-packages/sqlalchemy/engine/base.py", line 761, in _execute_clauseelement
    compiled_sql, distilled_params
  File "/usr/local/lib/python2.7/dist-packages/sqlalchemy/engine/base.py", line 874, in _execute_context
    context)
  File "/usr/local/lib/python2.7/dist-packages/sqlalchemy/engine/base.py", line 1024, in _handle_dbapi_exception
    exc_info
  File "/usr/local/lib/python2.7/dist-packages/sqlalchemy/util/compat.py", line 195, in raise_from_cause
    reraise(type(exception), exception, tb=exc_tb)
  File "/usr/local/lib/python2.7/dist-packages/sqlalchemy/engine/base.py", line 867, in _execute_context
    context)
  File "/usr/local/lib/python2.7/dist-packages/sqlalchemy/engine/default.py", line 324, in do_execute
    cursor.execute(statement, parameters)
  File "/usr/local/lib/python2.7/dist-packages/MySQLdb/cursors.py", line 201, in execute
    self.errorhandler(self, exc, value)
  File "/usr/local/lib/python2.7/dist-packages/MySQLdb/connections.py", line 36, in defaulterrorhandler
    raise errorclass, errorvalue
OperationalError: (OperationalError) (2006, 'MySQL server has gone away') 'SELECT category.id AS category_id, category.name AS category_name \nFROM category \nWHERE category.id = %s' (1L,)
2013-09-05 17:14:13,205 - Tornado - ERROR - Traceback (most recent call last):
  File "server.py", line 22, in <module>
    tornado.ioloop.IOLoop.instance().start()
  File "/usr/local/lib/python2.7/dist-packages/tornado/ioloop.py", line 646, in start
    event_pairs = self._impl.poll(poll_timeout)
KeyboardInterrupt

2013-09-07 15:08:07,133 - Tornado - ERROR - Traceback (most recent call last):
  File "server.py", line 22, in <module>
    tornado.ioloop.IOLoop.instance().start()
  File "/usr/local/lib/python2.7/dist-packages/tornado/ioloop.py", line 646, in start
    event_pairs = self._impl.poll(poll_timeout)
KeyboardInterrupt

